Workbook
Name AreaUnderMACYN: #REF!
Name BioenergyCropsYN: #REF!
Name BurdenSharing: #REF!
Name CapitalYN: #REF!
Name ClimateChange: #REF!
Name CoalYN: #REF!
Name ConsumptionLossYN: #REF!
Name ElectricityYN: #REF!
Name EmissionsPermitsYN: #REF!
Name EnergySystemCostMarkUpYN: #REF!
Name EquivalentVariationYN: #REF!
Name FoodCropsYN: #REF!
Name GasYN: #REF!
Name GDPLossYN: #REF!
Name ModelTypeSolutionConcept: #REF!
Name ModelTypeSolutionHorizon: #REF!
Name ModelTypeSolutionMethod: #REF!
Name ModelVersionStatus: #REF!
Name OilYN: #REF!
Name Overshoot: #REF!
Name ProcessedGoodsYN: #REF!
Name RegionalCoverage: #REF!
Name ScenarioType: #REF!
Name TechFlex: #REF!
Name UraniumYN: #REF!
Name WelfareLossYN: #REF!
Name WhatFlex: #REF!
Name WhenFlex: #REF!
Name WhenFlex2: #REF!
Name YN: #REF!

Sheet Listing_template
A1: Model | B1: Scenario | C1: Region | D1: Item | E1: Variable | F1: Year | G1: Unit | H1: Value
A2: … | B2: … | C2: WLD | D2: TOT | E2: POPT | F2: 2000 | G2: million
A3: … | B3: … | C3: … | D3: … | E3: … | F3: … | G3: …

Sheet Variables
C2: NEW LAMASUS SUGGESTIONS
B5: Variable | C5: Description | D5: Unit | E5: Total | F5: Rice | G5: Wheat | H5: Coarse grains | I5: Maize | J5: other coarse grains | K5: Oilseeds | L5: soya, rapeseed, sunflower | M5: other oilseeds and oil crops | N5: Sugar crops | O5: Vegetables, fruits & nuts | P5: Vegetables | Q5: Fruits | R5: Nuts | S5: Roots & tubers | T5: Pulses | U5: Plant based fibres | V5: Cotton | W5: other plant based fibres | X5: Energy crops | Y5: Other crops | Z5: All crops | AA5: Arable crops | AB5: Permanent crops | AC5: Ruminant meat | AD5: beef | AE5: Other ruminant | AF5: Non-ruminant meat | AG5: Pork meat | AH5: Poultry meat | AI5: Poultry eggs | AJ5: Other non-ruminant | AK5: Dairy | AL5: Other animal products | AM5: Livestock | AN5: Fish | AO5: Agriculture | AP5: Grass | AQ5: Other feed | AR5: Forest | AS5: Strict protection | AT5: Protected coniferous | AU5: Protected non-coniferous | AV5: Low intensity coniferous | AW5: Low intensity non-coniferous | AX5: High intensity coniferous | AY5: High intensity non-coniferous | AZ5: Restored protected coniferous | BA5: Restored protected non-coniferous | BB5: Restored unprotected coniferous | BC5: Restored unprotected non-coniferous | BD5: Managed Forest | BE5: Primary Forest | BF5: Woodchips Conifereous | BG5: Woodchips Non-conifereous | BH5: Sawdust Conifereous | BI5: Sawdust Non-conifereous | BJ5: Pulplogs Conifereous | BK5: Pulplogs Non-conifereous | BL5: Sawlogs Conifereous | BM5: Sawlogs Non-conifereous | BN5: Bark | BO5: Black Liquor | BP5: Agriculture and Forestry | BQ5: Other natural vegetation | BR5: Non arable land | BS5: Built-up area | BT5: Land-use change | BU5: Agriculture, Forestry, Land use-change | BV5: Wetland emissions | BW5: Enteric Fermentation | BX5: Manure applied to soils | BY5: Manure dropped on pasture | BZ5: Manure mangement | CA5: Rice cultivation | CB5: Synthetic fertilizer application | CC5: Labor | CD5: Capital | CE5: Fertiliser | CF5: Fossil fuel | CG5: Electricity | CH5: Primary agriculture & fish | CI5: Processed food sectors | CJ5: Food services | CK5: Non food sectors
E6: TOT | F6: RIC | G6: WHT | H6: CGR | I6: CGR|MAI | J6: CGR|OCG | K6: OSD | L6: OSD|SRS | M6: OSD|OOC | N6: SGC | O6: VFN | P6: VFN|VEG | Q6: VFN|FRU | R6: VFN|NUT | S6: VFN|ROOT | T6: VFN|PULS | U6: PFB | V6: PFB|COT | W6: PFB|OPF | X6: ECP | Y6: OCR | Z6: CRP | AA6: CRP|ARA | AB6: CRP|PRM | AC6: RUM | AD6: RUM|BEF | AE6: RUM|ORU | AF6: NRM | AG6: NRM|PRK | AH6: NRM|PTM | AI6: NRM|EGG | AJ6: NRM|ONR | AK6: DRY | AL6: OAP | AM6: LSP | AN6: FSH | AO6: AGR | AP6: GRS | AQ6: OFD | AR6: FOR | AS6: FOR|PRO | AT6: FOR|LOC | AU6: FOR|LON | AV6: FOR|MIC | AW6: FOR|MIN | AX6: FOR|HIC | AY6: FOR|HIN | AZ6: FOR|LRC | BA6: FOR|LRN | BB6: FOR|RUC | BC6: FOR|RUN | BD6: FOR|MAN | BE6: FOR|PRIM | BF6: FOR|WCC | BG6: FOR|WCN | BH6: FOR|SDC | BI6: FOR|SDN | BJ6: FOR|PLC | BK6: FOR|PLN | BL6: FOR|SLC | BM6: FOR|SLN | BN6: FOR|BRK | BO6: FOR|BLI | BP6: AFO | BQ6: ONV | BR6: NLD | BS6: BUA | BT6: LUC | BU6: AFOLU | BV6: WEM | BW6: ENT | BX6: MAS | BY6: MGR | BZ6: MMG | CA6: RCC | CB6: SFR | CC6: LAB | CD6: CAP | CE6: FRT | CF6: FF | CG6: ELEC | CH6: PRAG | CI6: PRFD | CJ6: PDSV | CK6: NONF | CL6: BC20
B7: POPT | C7: Total population | D7: million | E7: X
B8: GDPT | C8: Total GDP (MER) | D8: bn USD 2005 MER | E8: X
B9: XPRP | C9: Real producer price/input price | D9: USD/t | F9: X | G9: X | H9: X | K9: X | N9: X | O9: X | U9: X | X9: X | Y9: X | Z9: X | AC9: X | AF9: X | AK9: X | AL9: X | AM9: X | AN9: X | AO9: X | AR9: X
B10: XPRP_dm | C10: Real producer price/input price per unit dry matter content | D10: USD/t | F10: X | G10: X | H10: X | K10: X | N10: X | O10: X | U10: X | X10: X | Y10: X | Z10: X | AC10: X | AF10: X | AK10: X | AL10: X | AM10: X | AN10: X | AO10: X | AR10: X
B11: XPRX | C11: Real export price | D11: USD/t | F11: X | G11: X | H11: X | K11: X | N11: X | O11: X | U11: X | X11: X | Y11: X | Z11: X | AC11: X | AF11: X | AK11: X | AL11: X | AM11: X | AN11: X | AO11: X | AR11: X
B12: XPRX_dm | C12: Real export price per unit dry matter | D12: USD/t | F12: X | G12: X | H12: X | K12: X | N12: X | O12: X | U12: X | X12: X | Y12: X | Z12: X | AC12: X | AF12: X | AK12: X | AL12: X | AM12: X | AN12: X | AO12: X | AR12: X
B13: AREA | C13: Area harvested | D13: 1000 ha | E13: X | F13: X | G13: X | H13: X | I13: X | J13: X | K13: X | L13: X | M13: X | N13: X | O13: X | P13: X | Q13: X | R13: X | S13: X | T13: X | U13: X | V13: X | W13: X | X13: X | Y13: X | Z13: X | AA13: X | AB13: X | AC13: X | AD13: X | AE13: X | AF13: X | AG13: X | AH13: X | AI13: X | AJ13: X | AK13: X | AL13: X | AM13: X | AO13: X | AR13: X | AS13: X | AT13: X | AU13: X | AV13: X | AW13: X | AX13: X | AY13: X | AZ13: X | BA13: X | BB13: X | BC13: X | BD13: X | BE13: X
B14: ARRF | C14: Area harvested - rainfed | D14: 1000 ha | F14: X | G14: X | H14: X | I14: X | J14: X | K14: X | L14: X | M14: X | N14: X | O14: X | P14: X | Q14: X | R14: X | S14: X | T14: X | U14: X | V14: X | W14: X | X14: X | Y14: X | Z14: X | AA14: X | AB14: X
B15: ARIR | C15: Area harvested - irrigated | D15: 1000 ha | F15: X | G15: X | H15: X | I15: X | J15: X | K15: X | L15: X | M15: X | N15: X | O15: X | P15: X | Q15: X | R15: X | S15: X | T15: X | U15: X | V15: X | W15: X | X15: X | Y15: X | Z15: X | AA15: X | AB15: X
B16: LAND | C16: Land cover | D16: 1000 ha | E16: X | X16: X | Z16: X | AA16: X | AB16: X | AO16: X | AP16: X | AR16: X | BP16: X | BQ16: X | BS16: X
B17: YILD | C17: Crop yield | D17: t/ha | F17: X | G17: X | H17: X | K17: X | N17: X | O17: X | U17: X | X17: X | Y17: X | Z17: X | AP17: X
B18: YILD_dm | C18: Crop yield in dry matter content | D18: t/ha | F18: X | G18: X | H18: X | K18: X | N18: X | O18: X | U18: X | X18: X | Y18: X | Z18: X | AP18: X
B19: YIRF | C19: Crop yield - rainfed | D19: t/ha | F19: X | G19: X | H19: X | K19: X | N19: X | O19: X | U19: X | X19: X | Y19: X | Z19: X
B20: YIRF_dm | C20: Crop yield in dry matter content - rainfed | D20: t/ha | F20: X | G20: X | H20: X | K20: X | N20: X | O20: X | U20: X | X20: X | Y20: X | Z20: X
B21: YIIR | C21: Crop yield - irrigated | D21: t/ha | F21: X | G21: X | H21: X | K21: X | N21: X | O21: X | U21: X | X21: X | Y21: X | Z21: X
B22: YIIR_dm | C22: Crop yield in dry matter content - irrigated | D22: t/ha | F22: X | G22: X | H22: X | K22: X | N22: X | O22: X | U22: X | X22: X | Y22: X | Z22: X
B23: YEXO | C23: Exogenous crop yield (including climate shifter) | D23: t/ha | F23: X | G23: X | H23: X | K23: X | N23: X | O23: X | U23: X | X23: X | Y23: X | Z23: X | AP23: X
B24: YEXO_dm | C24: Exogenous crop yield in dry matter content (including climate shifter) | D24: t/ha | F24: X | G24: X | H24: X | K24: X | N24: X | O24: X | U24: X | X24: X | Y24: X | Z24: X | AP24: X
B25: YEXO_I | C25: Exogenous crop yield - Irrigated | D25: t/ha | F25: X | G25: X | H25: X | K25: X | N25: X | O25: X | U25: X | X25: X | Y25: X | Z25: X
B26: YEXO_I_dm | C26: Exogenous crop yield in dry matter content - Irrigated | D26: t/ha | F26: X | G26: X | H26: X | K26: X | N26: X | O26: X | U26: X | X26: X | Y26: X | Z26: X
B27: YEXO_R | C27: Exogenous crop yield - Rainfed | D27: t/ha | F27: X | G27: X | H27: X | K27: X | N27: X | O27: X | U27: X | X27: X | Y27: X | Z27: X
B28: YEXO_R_dm | C28: Exogenous crop yield in dry matter content - Rainfed | D28: t/ha | F28: X | G28: X | H28: X | K28: X | N28: X | O28: X | U28: X | X28: X | Y28: X | Z28: X
B29: YECC | C29: Climate change shifter on crop yield | D29: multiplier (unitless) | F29: X | G29: X | H29: X | K29: X | N29: X | O29: X | U29: X | X29: X | Y29: X | Z29: X | AP29: X
B30: YECC_I | C30: Climate change shifter on crop yield_Irrigated | D30: multiplier (unitless) | F30: X | G30: X | H30: X | K30: X | N30: X | O30: X | U30: X | X30: X | Y30: X | Z30: X
B31: YECC_R | C31: Climate change shifter on crop yield_Rainfed | D31: multiplier (unitless) | F31: X | G31: X | H31: X | K31: X | N31: X | O31: X | U31: X | X31: X | Y31: X | Z31: X
B32: LYLD | C32: Livestock yield (endogenous) | D32: kg prt/ha | AC32: X | AK32: X
B33: LYXO | C33: Exogenous livestock yield trend | D33: kg prt/ha | AC33: X | AK33: X
B34: FPROD | C34: Forestry production | D34: m3/yr | AR34: X | BD34: X | BF34: X | BG34: X | BH34: X | BI34: X | BJ34: X | BK34: X | BL34: X | BM34: X | BN34: X | BO34: X
B35: FCONS | C35: Forestry consumption | D35: m3/yr | AR35: X | BD35: X
B36: FNETT | C36: Forest products net trade | D36: m3/yr | AR36: X | BD36: X | BF36: X | BG36: X | BH36: X | BI36: X | BJ36: X | BK36: X | BL36: X | BM36: X | BN36: X | BO36: X
B37: FYLD | C37: Forestry yields | D37: m3/ha | AR37: X | BD37: X | BF37: X | BG37: X | BH37: X | BI37: X | BJ37: X | BK37: X | BL37: X | BM37: X | BN37: X | BO37: X
B38: FXPRP | C38: Real producer price/input price | D38: USD/m3 | AR38: X | BD38: x | BE38: x | BF38: X | BG38: X | BH38: X | BI38: X | BJ38: X | BK38: X | BL38: X | BM38: X | BN38: X | BO38: X
B39: FEEF | C39: Feed conversion efficiency (endogenous) | D39: kg prt/kg prt | AC39: X | AF39: X | AK39: X | AM39: X | AN39: X
B40: FOOD | C40: Food use | D40: 1000 t | F40: X | G40: X | H40: X | K40: X | N40: X | O40: X | U40: X | Y40: X | Z40: X | AC40: X | AF40: X | AK40: X | AL40: X | AM40: X | AN40: X | AO40: X
B41: FOOD_dm | C41: Food use in dry matter content | D41: 1000 t | F41: X | G41: X | H41: X | K41: X | N41: X | O41: X | U41: X | Y41: X | Z41: X | AC41: X | AF41: X | AK41: X | AL41: X | AM41: X | AN41: X | AO41: X
B42: FEED | C42: Feed use | D42: 1000 t | F42: X | G42: X | H42: X | K42: X | N42: X | O42: X | U42: X | Y42: X | Z42: X | AN42: X | AP42: X | AQ42: X
B43: FEED_dm | C43: Feed use in dry matter content | D43: 1000 t | F43: X | G43: X | H43: X | K43: X | N43: X | O43: X | U43: X | Y43: X | Z43: X | AN43: X | AP43: X | AQ43: X
...

Sheet Regions
A1: REGIONS TO BE REPORTED AND VALIDATED IN ACCELERATOR
A2: Regions | G2: MAPPING | K2: AgMIP | N2: country-NUTS1-NUTS2 mapping
A3: Code | B3: Region | C3: Details | D3: Comment | G3: Country | H3: ISO2 | I3: ISO3 | J3: ISO# | K3: AggCode | N3: Code 2021 | O3: Country | P3: NUTS level 1 | Q3: NUTS level 2
A4: CAN | B4: Canada | C4: Canada | G4: Afghanistan | H4: AF | I4: AFG | J4: 4 | K4: OAS | N4: BE10 | O4: Belgique/België | P4: Région de Bruxelles-Capitale/Brussels Hoofdstedelijk Gewest | Q4: Région de Bruxelles-Capitale/ Brussels Hoofdstedelijk Gewest
A5: USA | B5: USA | C5: United States of America | G5: Albania | H5: AL | I5: ALB | J5: 8 | K5: EUR | N5: BE21 | O5: Belgique/België | P5: Vlaams Gewest | Q5: Prov. Antwerpen
A6: BRA | B6: Brazil | C6: Brazil | G6: Algeria | H6: DZ | I6: DZA | J6: 12 | K6: MEN | N6: BE22 | O6: Belgique/België | P6: Vlaams Gewest | Q6: Prov. Limburg (BE)
A7: OSA | B7: Other S&C America | C7: Other South, Central America & Caribbean (incl. Mexico) | G7: Andorra | H7: AD | I7: AND | J7: 20 | K7: EUR | N7: BE23 | O7: Belgique/België | P7: Vlaams Gewest | Q7: Prov. Oost-Vlaanderen
A8: FSU | B8: Former Soviet Union | C8: Former Soviet Union (European and Asian) | G8: Angola | H8: AO | I8: AGO | J8: 24 | K8: SSA | N8: BE24 | O8: Belgique/België | P8: Vlaams Gewest | Q8: Prov. Vlaams-Brabant
A9: EUR | B9: Europe | C9: Europe (excl. Turkey) | G9: Anguilla | H9: AI | I9: AIA | J9: 660 | K9: OSA | N9: BE25 | O9: Belgique/België | P9: Vlaams Gewest | Q9: Prov. West-Vlaanderen
A10: MEN | B10: Middle-East/North Afr. | C10: Middle-East / North Africa (incl. Turkey) | G10: Antigua and Barbuda | H10: AG | I10: ATG | J10: 28 | K10: OSA | N10: BE31 | O10: Belgique/België | P10: Région wallonne | Q10: Prov. Brabant Wallon
A11: SSA | B11: Sub-Saharan Afr. | C11: Sub-Saharan Africa | G11: Argentina | H11: AR | I11: ARG | J11: 32 | K11: OSA | N11: BE32 | O11: Belgique/België | P11: Région wallonne | Q11: Prov. Hainaut
A12: CHN | B12: China | C12: China (incl Hong-Kong, Macao) | G12: Armenia | H12: AM | I12: ARM | J12: 51 | K12: FSU | N12: BE33 | O12: Belgique/België | P12: Région wallonne | Q12: Prov. Liège
A13: IND | B13: India | C13: India | G13: Aruba | H13: AW | I13: ABW | J13: 533 | K13: OSA | N13: BE34 | O13: Belgique/België | P13: Région wallonne | Q13: Prov. Luxembourg (BE)
A14: SEA | B14: South-East Asia | C14: South-East Asia (incl. Japan, Taiwan) | G14: Australia | H14: AU | I14: AUS | J14: 36 | K14: ANZ | N14: BE35 | O14: Belgique/België | P14: Région wallonne | Q14: Prov. Namur
A15: OAS | B15: Other Asia | C15: Other Asia (incl. Other Oceania) | G15: Austria | H15: AT | I15: AUT | J15: 40 | K15: EUR | N15: BG31 | O15: Bulgaria | P15: Severna i Yugoiztochna Bulgaria | Q15: Severozapaden
A16: ANZ | B16: Australia/New Zealand | C16: Australia/New Zealand | G16: Azerbaijan | H16: AZ | I16: AZE | J16: 31 | K16: FSU | N16: BG32 | O16: Bulgaria | P16: Severna i Yugoiztochna Bulgaria | Q16: Severen tsentralen
G17: Bahamas | H17: BS | I17: BHS | J17: 44 | K17: OSA | N17: BG33 | O17: Bulgaria | P17: Severna i Yugoiztochna Bulgaria | Q17: Severoiztochen
A18: NAM | B18: North America | C18: North America (Canada & USA) | D18: CAN+USA | G18: Bahrain | H18: BH | I18: BHR | J18: 48 | K18: MEN | N18: BG34 | O18: Bulgaria | P18: Severna i Yugoiztochna Bulgaria | Q18: Yugoiztochen
A19: OAM | B19: S&C America | C19: Other Americas (South, Central & Caribbean) | D19: BRA+OSA | G19: Bangladesh | H19: BD | I19: BGD | J19: 50 | K19: OAS | N19: BG41 | O19: Bulgaria | P19: Yugozapadna i Yuzhna tsentralna Bulgaria | Q19: Yugozapaden
A20: AME | B20: Africa & Middle East | C20: Africa & Middle East | D20: MEN + SSA | G20: Barbados | H20: BB | I20: BRB | J20: 52 | K20: OSA | N20: BG42 | O20: Bulgaria | P20: Yugozapadna i Yuzhna tsentralna Bulgaria | Q20: Yuzhen tsentralen
A21: SAS | B21: Southern Asia | C21: Southern Asia | D21: CHN + IND +SEA + OAS | G21: Belarus | H21: BY | I21: BLR | J21: 112 | K21: FSU | N21: CZ01 | O21: Česko | P21: Česko | Q21: Praha
G22: Belgium | H22: BE | I22: BEL | J22: 56 | K22: EUR | N22: CZ02 | O22: Česko | P22: Česko | Q22: Střední Čechy
A23: WLD | B23: World | C23: World | G23: Belize | H23: BZ | I23: BLZ | J23: 84 | K23: OSA | N23: CZ03 | O23: Česko | P23: Česko | Q23: Jihozápad
G24: Benin | H24: BJ | I24: BEN | J24: 204 | K24: SSA | N24: CZ04 | O24: Česko | P24: Česko | Q24: Severozápad
A25: European Union | G25: Bermuda | H25: BM | I25: BMU | J25: 60 | K25: OSA | N25: CZ05 | O25: Česko | P25: Česko | Q25: Severovýchod
A26: EUE | B26: European Union | C26: EU27 Members States | G26: Bhutan | H26: BT | I26: BTN | J26: 64 | K26: OAS | N26: CZ06 | O26: Česko | P26: Česko | Q26: Jihovýchod
A27: AUT | B27: Austria | G27: Bolivia | H27: BO | I27: BOL | J27: 68 | K27: OSA | N27: CZ07 | O27: Česko | P27: Česko | Q27: Střední Morava
A28: BEL | B28: Belgium | G28: Bosnia and Herzegovina | H28: BA | I28: BIH | J28: 70 | K28: EUR | N28: CZ08 | O28: Česko | P28: Česko | Q28: Moravskoslezsko
A29: BGR | B29: Bulgaria | G29: Botswana | H29: BW | I29: BWA | J29: 72 | K29: SSA | N29: DK01 | O29: Danmark | P29: Danmark | Q29: Hovedstaden
A30: CYP | B30: Cyprus | G30: Brazil | H30: BR | I30: BRA | J30: 76 | K30: BRA | N30: DK02 | O30: Danmark | P30: Danmark | Q30: Sjælland
A31: CZE | B31: Czech Republic | G31: British Virgin Islands | H31: VG | I31: VGB | J31: 92 | K31: OSA | N31: DK03 | O31: Danmark | P31: Danmark | Q31: Syddanmark
A32: DEU | B32: Germany | G32: Brunei Darussalam | H32: BN | I32: BRN | J32: 96 | K32: SEA | N32: DK04 | O32: Danmark | P32: Danmark | Q32: Midtjylland
A33: DNK | B33: Denmark | G33: Bulgaria | H33: BG | I33: BGR | J33: 100 | K33: EUR | N33: DK05 | O33: Danmark | P33: Danmark | Q33: Nordjylland
A34: ESP | B34: Spain | G34: Burkina Faso | H34: BF | I34: BFA | J34: 854 | K34: SSA | N34: DE11 | O34: Deutschland | P34: Baden-Württemberg | Q34: Stuttgart
A35: EST | B35: Estonia | G35: Burundi | H35: BI | I35: BDI | J35: 108 | K35: SSA | N35: DE12 | O35: Deutschland | P35: Baden-Württemberg | Q35: Karlsruhe
A36: FIN | B36: Finland | G36: Cambodia | H36: KH | I36: KHM | J36: 116 | K36: SEA | N36: DE13 | O36: Deutschland | P36: Baden-Württemberg | Q36: Freiburg
A37: FRA | B37: France | G37: Cameroon | H37: CM | I37: CMR | J37: 120 | K37: SSA | N37: DE14 | O37: Deutschland | P37: Baden-Württemberg | Q37: Tübingen
A38: GRC | B38: Greece | G38: Canada | H38: CA | I38: CAN | J38: 124 | K38: CAN | N38: DE21 | O38: Deutschland | P38: Bayern | Q38: Oberbayern
... A58: REU | B58: Rest of Europe | G58: Djibouti | H58: DJ | I58: DJI | J58: 262 | K58: SSA | N58: DEA2 | O58: Deutschland | P58: Nordrhein-Westfalen | Q58: Köln
G59: Dominica | H59: DM | I59: DMA | J59: 212 | K59: OSA | N59: DEA3 | O59: Deutschland | P59: Nordrhein-Westfalen | Q59: Münster
...

Sheet Units
A1: Units | B1: Description
A2: million
A3: bn USD 2005 MER
A4: USD/t
A5: 1000 ha
A6: t/ha
A7: multiplier (unitless)
A8: kg prt/ha
A9: kg prt/kg prt
A10: 1000 t
A11: km3
A12: kcal/cap/d
A13: LSU | B13: livestock units, see https://ec.europa.eu/eurostat/statistics-explained/index.php?title=Glossary:Livestock_unit_(LSU)
A14: MtCO2e
A15: tCH4
A16: tN2O
A17: USD/tCO2e
A18: BII
A19: tC/ha
A20: 1000 t
A21: tN
A22: tP
A23: Mt NH3
A24: t | B24: tons
A25: 1000 head | B25: livestock numbers
A26: gprt/cap/day | B26: gram proteins per capita per day

Sheet Items
A2: Reporting sectors | E2: Commnets
B3: Code | C3: Description | D3: Link to GTAP sectors | E3: CAPRI | F3: AGMEMOD | G3: GLOBIOM | H3: IMAGE | I3: MAGNET
B4: RIC | C4: Rice (paddy equivalent) | D4: pdr (+ pcr in raw eq.) | F4: RE | I4: Only primary production
B5: WHT | C5: Wheat | D5: wht | F5: GR
B6: CGR | C6: Other cereal grains | D6: gro
B7: OSD | C7: Oilseeds and oil crops (raw equivalent) | D7: osd (+ vol in raw eq.) | I7: Only primary production
B8: SGC | C8: Sugar crops (raw equivalent) | D8: c_b (+ sgr in raw eq.) | I8: Only primary production
B9: VFN | C9: Vegetables, fruits, nuts (incl. roots and tubers) | D9: v_f
B10: PFB | C10: Plant based fibres | D10: pfb | I10: Refers to seed cotton, unginned for production and area
B11: ECP | C11: Energy crops | I11: Not explicitely present
B12: OCR | C12: Other crops | D12: ocr
B13: RUM | C13: Ruminant meats | D13: ctl (+ cmt in raw eq.) | I13: Only primary production
B14: NRM | C14: Non ruminant meats | D14: oap (+ omt in raw eq.) | I14: Only primary production
B15: DRY | C15: Dairy (raw milk equivalent) | D15: rmk (+ mil in raw eq.) | I15: Only primary production
B16: OAP | C16: Other animal products (wool, honey) | D16: wol
B17: GRS | C17: Grass
B18: OFD | C18: Other feed products
B19: FSH | C19: Fish | D19: fsh
B20: FOR | C20: Forestry products | D20: frs
A21: Sectors subcategories (same variables as parents)
B22: VFN|VEG | C22: Vegetables | D22: definition to be clarified in sheet "overview crop definitions" | I22: Available
B23: VFN|FRU | C23: Fruits | D23: definition to be clarified in sheet "overview crop definitions" | I23: Available
B24: VFN|NUT | C24: Nuts | D24: definition to be clarified in sheet "overview crop definitions" | I24: Available
B25: VFN|ROOT | C25: Roots & tubers | D25: definition to be clarified in sheet "overview crop definitions" | I25: Available
B26: VFN|PULS | C26: Pulses | D26: definition to be clarified in sheet "overview crop definitions" | I26: Available
B27: PFB|COT | C27: Cotton | I27: NA
B28: PFB|OPF | C28: other plant based fibres | I28: NA
B29: CGR|MAI | C29: Maize | I29: NA
B30: CGR|OCG | C30: other coarse grains | I30: NA
B31: OSD|SRS | C31: soya, rapeseed, sunflower | I31: NA
B32: OSD|OOC | C32: other oilseeds and oil crops | I32: NA
B33: NRM|PRK | C33: Pork meat | F33: NRM|PK | I33: NA
B34: NRM|PTM | C34: Poultry meat | F34: NRM|PTM | I34: NA
B35: NRM|EGG | C35: Poultry eggs | F35: NRM|PO | I35: NA
B36: NRM|ONR | C36: Other non-ruminant | F36: NRM|EG | I36: NA
B37: RUM|BEF | C37: beef | I37: Available
B38: RUM|ORU | C38: Other ruminant | I38: Available
B39: CRP|ARA | C39: Arable crops | I39: NA
B40: CRP|PRM | C40: Permanent crops | I40: NA
A41: Sectors aggregates
...

Sheet Overview crop definitions
B1: Crop definitions based on gtap categories, and inspired on Table 2.1. of 'Economic Analysis of Land Use in Global Climate Change Policy', W. Hertel, 2009.
D2: % filters for most important crops based on world harvest area FAO
F4: Definitions in models (please add the best matching AgMIP category for each crop):
B5: Crop FAO | C5: AgMIP cat | D5: % area in AgMIP cat | E5: % Area all cat | F5: AIM/CGE | G5: GCAM | H5: MAgPIE | I5: MAGNET | J5: IMAGE | K5: GLOBIOM | L5: Impact | M5: CAPRI | N5: CLUMONDO | O5: AGMEMOD | P5: CGR | Q5: CGR2 | R5: CGR3 | S5: Column1
B6: Rice, paddy | C6: RIC | D6: 1 | E6: 0.12463543 | I6: RIC | J6: RIC | K6: RIC | L6: RIC | M6: RIC | N6: ARA | O6: RIC | P6: CGR | Q6: CGR
B7: Wheat | C7: WHT | D7: 1 | E7: 0.16659063 | I7: WHT | J7: WHT | K7: WHT | L7: WHT | M7: WHT | N7: ARA | O7: WHT | P7: CGR | Q7: CGR
B8: Maize | C8: CGR | D8: 0.51810527 | E8: 0.12646508 | I8: CGR | J8: CGR | K8: CGR | L8: CGR | M8: CGR|MAI | N8: ARA | O8: CGR|MAI | P8: CGR | Q8: CGR
B9: Barley | C9: CGR | D9: 0.14953728 | E9: 0.036500775 | I9: CGR | J9: CGR | K9: CGR | L9: CGR | M9: CGR|OCG | N9: ARA | O9: CGR|OCG
B10: Sorghum | C10: CGR | D10: 0.13330185 | E10: 0.032537847 | I10: CGR | J10: CGR | K10: CGR | L10: CGR | M10: CGR|OCG | N10: ARA | O10: CGR|OCG
B11: Millet | C11: CGR | D11: 0.11442755 | E11: 0.027930791 | I11: CGR | J11: CGR | K11: CGR | L11: CGR | M11: CGR|OCG | N11: ARA | O11: CGR|OCG
B12: Oats | C12: CGR | D12: 0.028732143 | E12: 0.0070132713 | I12: CGR | J12: CGR | L12: CGR | M12: CGR|OCG | N12: ARA | O12: CGR|OCG
B13: Rye | C13: CGR | D13: 0.015875845 | E13: 0.0038751586 | I13: CGR | J13: CGR | L13: CGR | M13: CGR|OCG | N13: ARA | O13: CGR|OCG
B14: Cereals, nes | C14: CGR | D14: 0.01434593 | E14: 0.0035017194 | I14: CGR | J14: CGR | L14: CGR | M14: CGR|OCG | N14: ARA | O14: CGR|OCG
B15: Triticale | C15: CGR | D15: 0.012640217 | E15: 0.0030853694 | I15: CGR | J15: CGR | L15: CGR | M15: CGR|OCG | N15: ARA | O15: CGR|OCG
B16: Buckwheat | C16: CGR | D16: 0.0060383838 | E16: 0.001473918 | I16: CGR | J16: CGR | L16: CGR | M16: CGR|OCG | N16: ARA
B17: Grain, mixed | C17: CGR | D17: 0.0039917897 | E17: 0.00097436186 | I17: CGR | J17: CGR | L17: CGR | M17: CGR|OCG | N17: ARA
B18: Fonio | C18: CGR | D18: 0.0018402322 | E18: 0.000449185 | I18: CGR | J18: CGR | L18: CGR | M18: CGR|OCG | N18: ARA
B19: Canary seed | C19: CGR | D19: 0.0008606072 | E19: 0.00021006689 | I19: CGR | J19: CGR | L19: CGR | M19: CGR|OCG | N19: ARA
B20: Quinoa | C20: CGR | D20: 0.00030290286 | E20: 7.393601e-05 | I20: CGR | J20: CGR | L20: CGR | M20: CGR|OCG | N20: ARA
B21: Coffee, green | C21: OCR | D21: 0.29541608 | E21: 0.0081150068 | I21: OCR | J21: OCR | L21: OCR | M21: OCR | N21: PRM
B22: Cocoa, beans | C22: OCR | D22: 0.27016925 | E22: 0.0074214827 | I22: OCR | J22: OCR | L22: OCR | M22: OCR | N22: PRM
B23: Tobacco, unmanufactured | C23: OCR | D23: 0.11090779 | E23: 0.0030466098 | I23: OCR | J23: OCR | L23: OCR | M23: OCR | N23: ARA
B24: Tea | C24: OCR | D24: 0.088325494 | E24: 0.0024262795 | I24: OCR | J24: OCR | L24: OCR | M24: OCR | N24: PRM
B25: Chillies and peppers, dry | C25: OCR | D25: 0.052848878 | E25: 0.0014517457 | I25: OCR | J25: OCR | L25: VFN | M25: OCR | N25: ARA
B26: Roots and tubers, nes | C26: OCR | D26: 0.03396986 | E26: 0.00093314367 | I26: OCR | J26: VFN | L26: OCR | M26: VFN|ROOT | N26: ARA | O26: VFN|ROOT
B27: Spices, nes | C27: OCR | D27: 0.027131129 | E27: 0.00074528544 | I27: OCR | J27: OCR | L27: OCR | M27: OCR | N27: PRM
B28: Lupins | C28: OCR | D28: 0.026696772 | E28: 0.00073335375 | I28: OCR | J28: VFN | L28: OCR | M28: VFN|PULS | N28: ARA | O28: VFN|PULS
B29: Anise, badian, fennel, coriander | C29: OCR | D29: 0.026208103 | E29: 0.00071993013 | I29: OCR | J29: OCR | L29: OCR | M29: OCR | N29: PRM
B30: Pepper (piper spp.) | C30: OCR | D30: 0.015869101 | E30: 0.00043592029 | I30: OCR | J30: OCR | L30: OCR | M30: OCR | N30: PRM
B31: Vetches | C31: OCR | D31: 0.014085813 | E31: 0.00038693381 | I31: OCR | J31: VFN | L31: OCR | M31: OCR | N31: ARA
B32: Cloves | C32: OCR | D32: 0.010927225 | E32: 0.00030016818 | I32: OCR | J32: OCR | L32: OCR | M32: OCR | N32: ARA
B33: Nutmeg, mace and cardamoms | C33: OCR | D33: 0.0083065355 | E33: 0.00022817848 | I33: OCR | J33: OCR | L33: OCR | M33: OCR | N33: PRM
B34: Ginger | C34: OCR | D34: 0.0075465019 | E34: 0.00020730055 | I34: OCR | J34: OCR | L34: OCR | M34: OCR | N34: PRM
B35: Cinnamon (canella) | C35: OCR | D35: 0.0064575059 | E35: 0.0001773861 | I35: OCR | J35: OCR | L35: OCR | M35: OCR | N35: PRM
B36: Vanilla | C36: OCR | D36: 0.0024225652 | E36: 6.6547269e-05 | I36: OCR | J36: OCR | L36: OCR | M36: OCR | N36: PRM
B37: Hops | C37: OCR | D37: 0.0021767562 | E37: 5.9794956e-05 | I37: OCR | J37: OCR | L37: OCR | M37: OCR | N37: PRM | R37: OSD
B38: Pyrethrum, dried | C38: OCR | D38: 0.00045673912 | E38: 1.2546511e-05 | I38: OCR | J38: OCR | L38: OCR | M38: OCR | N38: ARA
B39: Peppermint | C39: OCR | D39: 7.7901766e-05 | E39: 2.1399423e-06 | I39: OCR | J39: OCR | L39: OCR | M39: OCR | N39: ARA
B40: Soybeans | C40: OSD | D40: 0.43341346 | E40: 0.079338255 | I40: OSD | J40: OSD | K40: OSD | L40: OSD | M40: OSD|SRS | N40: ARA | O40: OSD|SRS
B41: Rapeseed | C41: OSD | D41: 0.13583429 | E41: 0.024865068 | I41: OSD | J41: OSD | K41: OSD | L41: OSD | M41: OSD|SRS | N41: ARA | O41: OSD|SRS
...

Sheet Overview regional mapping
A1: AgMIP | C1: MAPPING | H1: Only deviations listed! | S1: CAPRI | W1: GLOBIOM | AA1: IMAGE | AE1: MAGNET | AJ1: IMPACT | AQ1: FAO
A2: AgMIP | B2: Descr | C2: Country | D2: ISO2 | E2: ISO3 | F2: ISO# | G2: % of world population | H2: GLOBIOM | I2: IMAGE | J2: CAPRI | K2: MAGNET | L2: IMPACT | S2: CAPRI | T2: ISO | U2: AGMIP | W2: ISO3 | X2: ALLCOUNTRY | Y2: AgMIP region | AA2: iso3 | AB2: IMAGE_reg_name | AC2: AGMIP_reg_name | AE2: ISO | AF2: GTAP | AG2: MAGNET | AH2: AgMIP | AJ2: ISO3 | AK2: IMPACT_CTY | AL2: AgMIP_Level_1 | AM2: AgMIP_Level_2 | AN2: AgMIP_Level_3 | AO2: Notes and exceptions (**) to AgMIP | AQ2: Area Code (ISO3) | AR2: Area | AS2: Element | AT2: Item | AU2: Year | AV2: Unit | AW2: Value
A3: ANZ | B3: =INDEX(Regions!B:B,MATCH(A3,Regions!A:A,0)) -> Australia/New Zealand | C3: Australia | D3: AU | E3: AUS | F3: 36 | G3: =INDEX(AW:AW,MATCH(E3,AQ:AQ,0))/INDEX(AW:AW,MATCH("World",AR:AR,0)) -> 0.0032344734 | H3: =IF(INDEX(Y:Y,MATCH(E3,W:W,0))=A3,"",INDEX(Y:Y,MATCH(E3,W:W,0))) | I3: =IF(INDEX(AC:AC,MATCH(E3,AA:AA,0))=A3,"",INDEX(AC:AC,MATCH(E3,AA:AA,0))) | J3: =IF(INDEX(U:U,MATCH(E3,T:T,0))=A3,"",INDEX(U:U,MATCH(E3,T:T,0))) | K3: =IF(INDEX(AH:AH,MATCH(E3,AE:AE,0))=A3,"",INDEX(AH:AH,MATCH(E3,AE:AE,0))) | S3: #N/A | T3: ABW | U3: #N/A | W3: ARG | X3: Argentina | Y3: OSA | AA3: CAN | AB3: Canada | AC3: CAN | AE3: AUS | AF3: aus | AG3: OCE | AH3: ANZ | AJ3: ABW | AK3: CRB | AL3: OSA | AN3: WLD | AQ3: AFG | AR3: Afghanistan | AS3: Total Population - Both sexes | AT3: Population - Est. & Proj. | AU3: 2014 | AV3: 1000 persons | AW3: 33370.794
A4: ANZ | B4: =INDEX(Regions!B:B,MATCH(A4,Regions!A:A,0)) -> Australia/New Zealand | C4: New Zealand | D4: NZ | E4: NZL | F4: 554 | G4: =INDEX(AW:AW,MATCH(E4,AQ:AQ,0))/INDEX(AW:AW,MATCH("World",AR:AR,0)) -> 0.00062609252 | H4: =IF(INDEX(Y:Y,MATCH(E4,W:W,0))=A4,"",INDEX(Y:Y,MATCH(E4,W:W,0))) | I4: =IF(INDEX(AC:AC,MATCH(E4,AA:AA,0))=A4,"",INDEX(AC:AC,MATCH(E4,AA:AA,0))) | J4: =IF(INDEX(U:U,MATCH(E4,T:T,0))=A4,"",INDEX(U:U,MATCH(E4,T:T,0))) | K4: =IF(INDEX(AH:AH,MATCH(E4,AE:AE,0))=A4,"",INDEX(AH:AH,MATCH(E4,AE:AE,0))) | S4: ASOCE_LDC | T4: AFG | U4: OAS | W4: AUS | X4: Australia | Y4: ANZ | AA4: SPM | AB4: USA | AC4: USA | AE4: CXR | AF4: aus | AG4: OCE | AH4: ANZ | AJ4: AFG | AK4: AFG | AL4: OAS | AM4: SAS | AN4: WLD | AQ4: ALB | AR4: Albania | AS4: Total Population - Both sexes | AT4: Population - Est. & Proj. | AU4: 2014 | AV4: 1000 persons | AW4: 2896.305
A5: BRA | B5: =INDEX(Regions!B:B,MATCH(A5,Regions!A:A,0)) -> Brazil | C5: Brazil | D5: BR | E5: BRA | F5: 76 | G5: =INDEX(AW:AW,MATCH(E5,AQ:AQ,0))/INDEX(AW:AW,MATCH("World",AR:AR,0)) -> 0.027793784 | H5: =IF(INDEX(Y:Y,MATCH(E5,W:W,0))=A5,"",INDEX(Y:Y,MATCH(E5,W:W,0))) | I5: =IF(INDEX(AC:AC,MATCH(E5,AA:AA,0))=A5,"",INDEX(AC:AC,MATCH(E5,AA:AA,0))) | J5: =IF(INDEX(U:U,MATCH(E5,T:T,0))=A5,"",INDEX(U:U,MATCH(E5,T:T,0))) | K5: =IF(INDEX(AH:AH,MATCH(E5,AE:AE,0))=A5,"",INDEX(AH:AH,MATCH(E5,AE:AE,0))) | S5: AFR_LDC | T5: AGO | U5: SSA | W5: BRA | X5: Brazil | Y5: BRA | AA5: USA | AB5: USA | AC5: USA | AE5: CCK | AF5: aus | AG5: OCE | AH5: ANZ | AJ5: AGO | AK5: AGO | AL5: SSA | AM5: AME | AN5: WLD | AQ5: DZA | AR5: Algeria | AS5: Total Population - Both sexes | AT5: Population - Est. & Proj. | AU5: 2014 | AV5: 1000 persons | AW5: 38923.692
A6: CAN | B6: =INDEX(Regions!B:B,MATCH(A6,Regions!A:A,0)) -> Canada | C6: Canada | D6: CA | E6: CAN | F6: 124 | G6: =INDEX(AW:AW,MATCH(E6,AQ:AQ,0))/INDEX(AW:AW,MATCH("World",AR:AR,0)) -> 0.0048886793 | H6: =IF(INDEX(Y:Y,MATCH(E6,W:W,0))=A6,"",INDEX(Y:Y,MATCH(E6,W:W,0))) | I6: =IF(INDEX(AC:AC,MATCH(E6,AA:AA,0))=A6,"",INDEX(AC:AC,MATCH(E6,AA:AA,0))) | J6: =IF(INDEX(U:U,MATCH(E6,T:T,0))=A6,"",INDEX(U:U,MATCH(E6,T:T,0))) | K6: =IF(INDEX(AH:AH,MATCH(E6,AE:AE,0))=A6,"",INDEX(AH:AH,MATCH(E6,AE:AE,0))) | S6: AL000000 | T6: ALB | U6: EUR | W6: CAN | X6: Canada | Y6: CAN | AA6: UMI | AB6: USA | AC6: USA | AE6: HMD | AF6: aus | AG6: OCE | AH6: ANZ | AJ6: AIA | AK6: CRB | AL6: OSA | AN6: WLD | AQ6: ASM | AR6: American Samoa | AS6: Total Population - Both sexes | AT6: Population - Est. & Proj. | AU6: 2014 | AV6: 1000 persons | AW6: 55.791
A7: CHN | B7: =INDEX(Regions!B:B,MATCH(A7,Regions!A:A,0)) -> China | C7: China | D7: CN | E7: CHN | F7: 156 | G7: =INDEX(AW:AW,MATCH(E7,AQ:AQ,0))/INDEX(AW:AW,MATCH("World",AR:AR,0)) -> 0.19610881 | H7: =IF(INDEX(Y:Y,MATCH(E7,W:W,0))=A7,"",INDEX(Y:Y,MATCH(E7,W:W,0))) | I7: =IF(INDEX(AC:AC,MATCH(E7,AA:AA,0))=A7,"",INDEX(AC:AC,MATCH(E7,AA:AA,0))) | J7: =IF(INDEX(U:U,MATCH(E7,T:T,0))=A7,"",INDEX(U:U,MATCH(E7,T:T,0))) | K7: =IF(INDEX(AH:AH,MATCH(E7,AE:AE,0))=A7,"",INDEX(AH:AH,MATCH(E7,AE:AE,0))) | S7: MIDEAST | T7: ARE | U7: MEN | W7: CHN | X7: China | Y7: CHN | AA7: MEX | AB7: Mexico | AC7: OSA | AE7: NFK | AF7: aus | AG7: OCE | AH7: ANZ | AJ7: ALA | AK7: FNP | AL7: EUR | AN7: WLD | AO7: Åland Islands | AQ7: AND | AR7: Andorra | AS7: Total Population - Both sexes | AT7: Population - Est. & Proj. | AU7: 2014 | AV7: 1000 persons | AW7: 79.213
A8: CHN | B8: =INDEX(Regions!B:B,MATCH(A8,Regions!A:A,0)) -> China | C8: Hong Kong | D8: HK | E8: HKG | F8: 344 | G8: =INDEX(AW:AW,MATCH(E8,AQ:AQ,0))/INDEX(AW:AW,MATCH("World",AR:AR,0)) -> 0.00097798295 | H8: =IF(INDEX(Y:Y,MATCH(E8,W:W,0))=A8,"",INDEX(Y:Y,MATCH(E8,W:W,0))) -> NotAccounted | I8: =IF(INDEX(AC:AC,MATCH(E8,AA:AA,0))=A8,"",INDEX(AC:AC,MATCH(E8,AA:AA,0))) | J8: =IF(INDEX(U:U,MATCH(E8,T:T,0))=A8,"",INDEX(U:U,MATCH(E8,T:T,0))) -> #N/A | K8: =IF(INDEX(AH:AH,MATCH(E8,AE:AE,0))=A8,"",INDEX(AH:AH,MATCH(E8,AE:AE,0))) | S8: ARG | T8: ARG | U8: OSA | W8: CMR | X8: Cameroon | Y8: SSA | AA8: AIA | AB8: Rest Central America | AC8: OSA | AE8: NZL | AF8: nzl | AG8: OCE | AH8: ANZ | AJ8: ALB | AK8: ALB | AL8: EUR | AN8: WLD | AQ8: AGO | AR8: Angola | AS8: Total Population - Both sexes | AT8: Population - Est. & Proj. | AU8: 2014 | AV8: 1000 persons | AW8: 26941.779
A9: CHN | B9: =INDEX(Regions!B:B,MATCH(A9,Regions!A:A,0)) -> China | C9: Macao, China | D9: MO | E9: MAC | F9: 446 | G9: =INDEX(AW:AW,MATCH(E9,AQ:AQ,0))/INDEX(AW:AW,MATCH("World",AR:AR,0)) -> 8.0902601e-05 | H9: =IF(INDEX(Y:Y,MATCH(E9,W:W,0))=A9,"",INDEX(Y:Y,MATCH(E9,W:W,0))) -> NotAccounted | I9: =IF(INDEX(AC:AC,MATCH(E9,AA:AA,0))=A9,"",INDEX(AC:AC,MATCH(E9,AA:AA,0))) | J9: =IF(INDEX(U:U,MATCH(E9,T:T,0))=A9,"",INDEX(U:U,MATCH(E9,T:T,0))) -> #N/A | K9: =IF(INDEX(AH:AH,MATCH(E9,AE:AE,0))=A9,"",INDEX(AH:AH,MATCH(E9,AE:AE,0))) | S9: FSU | T9: ARM | U9: FSU | W9: CAF | X9: CentAfrRep | Y9: SSA | AA9: ATG | AB9: Rest Central America | AC9: OSA | AE9: ASM | AF9: xoc | AG9: IDN | AH9: SEA | AJ9: AND | AK9: SPP | AL9: EUR | AN9: WLD | AQ9: AIA | AR9: Anguilla | AS9: Total Population - Both sexes | AT9: Population - Est. & Proj. | AU9: 2014 | AV9: 1000 persons | AW9: 14.112
A10: EUR | B10: =INDEX(Regions!B:B,MATCH(A10,Regions!A:A,0)) -> Europe | C10: Albania | D10: AL | E10: ALB | F10: 8 | G10: =INDEX(AW:AW,MATCH(E10,AQ:AQ,0))/INDEX(AW:AW,MATCH("World",AR:AR,0)) -> 0.00039701022 | H10: =IF(INDEX(Y:Y,MATCH(E10,W:W,0))=A10,"",INDEX(Y:Y,MATCH(E10,W:W,0))) | I10: =IF(INDEX(AC:AC,MATCH(E10,AA:AA,0))=A10,"",INDEX(AC:AC,MATCH(E10,AA:AA,0))) | J10: =IF(INDEX(U:U,MATCH(E10,T:T,0))=A10,"",INDEX(U:U,MATCH(E10,T:T,0))) | K10: =IF(INDEX(AH:AH,MATCH(E10,AE:AE,0))=A10,"",INDEX(AH:AH,MATCH(E10,AE:AE,0))) | S10: #N/A | T10: ASM | U10: #N/A | W10: COG | X10: CongoRep | Y10: SSA | AA10: ABW | AB10: Rest Central America | AC10: OSA | AE10: COK | AF10: xoc | AG10: IDN | AH10: SEA | AJ10: ANT | AK10: CRB | AL10: OSA | AN10: WLD | AQ10: ATG | AR10: Antigua and Barbuda | AS10: Total Population - Both sexes | AT10: Population - Est. & Proj. | AU10: 2014 | AV10: 1000 persons | AW10: 92.562
A11: EUR | B11: =INDEX(Regions!B:B,MATCH(A11,Regions!A:A,0)) -> Europe | C11: Andorra | D11: AD | E11: AND | F11: 20 | G11: =INDEX(AW:AW,MATCH(E11,AQ:AQ,0))/INDEX(AW:AW,MATCH("World",AR:AR,0)) -> 1.08581e-05 | H11: =IF(INDEX(Y:Y,MATCH(E11,W:W,0))=A11,"",INDEX(Y:Y,MATCH(E11,W:W,0))) -> NotAccounted | I11: =IF(INDEX(AC:AC,MATCH(E11,AA:AA,0))=A11,"",INDEX(AC:AC,MATCH(E11,AA:AA,0))) | J11: =IF(INDEX(U:U,MATCH(E11,T:T,0))=A11,"",INDEX(U:U,MATCH(E11,T:T,0))) -> #N/A | K11: =IF(INDEX(AH:AH,MATCH(E11,AE:AE,0))=A11,"",INDEX(AH:AH,MATCH(E11,AE:AE,0))) | S11: MSA_ACP | T11: ATG | U11: OSA | W11: COD | X11: CongoDemR | Y11: SSA | AA11: BHS | AB11: Rest Central America | AC11: OSA | AE11: FJI | AF11: xoc | AG11: IDN | AH11: SEA | AJ11: ARE | AK11: RAP | AL11: MEN | AM11: AME | AN11: WLD | AQ11: ARG | AR11: Argentina | AS11: Total Population - Both sexes | AT11: Population - Est. & Proj. | AU11: 2014 | AV11: 1000 persons | AW11: 42637.511
A12: EUR | B12: =INDEX(Regions!B:B,MATCH(A12,Regions!A:A,0)) -> Europe | C12: Austria | D12: AT | E12: AUT | F12: 40 | G12: =INDEX(AW:AW,MATCH(E12,AQ:AQ,0))/INDEX(AW:AW,MATCH("World",AR:AR,0)) -> 0.0011809281 | H12: =IF(INDEX(Y:Y,MATCH(E12,W:W,0))=A12,"",INDEX(Y:Y,MATCH(E12,W:W,0))) | I12: =IF(INDEX(AC:AC,MATCH(E12,AA:AA,0))=A12,"",INDEX(AC:AC,MATCH(E12,AA:AA,0))) | J12: =IF(INDEX(U:U,MATCH(E12,T:T,0))=A12,"",INDEX(U:U,MATCH(E12,T:T,0))) | K12: =IF(INDEX(AH:AH,MATCH(E12,AE:AE,0))=A12,"",INDEX(AH:AH,MATCH(E12,AE:AE,0))) | S12: AUS | T12: AUS | U12: ANZ | W12: GNQ | X12: EqGuinea | Y12: SSA | AA12: BRB | AB12: Rest Central America | AC12: OSA | AE12: PYF | AF12: xoc | AG12: IDN | AH12: SEA | AJ12: ARG | AK12: ARG | AL12: OSA | AM12: OAM | AN12: WLD | AQ12: ARM | AR12: Armenia | AS12: Total Population - Both sexes | AT12: Population - Est. & Proj. | AU12: 2014 | AV12: 1000 persons | AW12: 2912.409
A13: EUR | B13: =INDEX(Regions!B:B,MATCH(A13,Regions!A:A,0)) -> Europe | C13: Belgium | D13: BE | E13: BEL | F13: 56 | G13: =INDEX(AW:AW,MATCH(E13,AQ:AQ,0))/INDEX(AW:AW,MATCH("World",AR:AR,0)) -> 0.0015381472 | H13: =IF(INDEX(Y:Y,MATCH(E13,W:W,0))=A13,"",INDEX(Y:Y,MATCH(E13,W:W,0))) | I13: =IF(INDEX(AC:AC,MATCH(E13,AA:AA,0))=A13,"",INDEX(AC:AC,MATCH(E13,AA:AA,0))) | J13: =IF(INDEX(U:U,MATCH(E13,T:T,0))=A13,"",INDEX(U:U,MATCH(E13,T:T,0))) | K13: =IF(INDEX(AH:AH,MATCH(E13,AE:AE,0))=A13,"",INDEX(AH:AH,MATCH(E13,AE:AE,0))) | S13: AT000000 | T13: AUT | U13: EUR | W13: GAB | X13: Gabon | Y13: SSA | AA13: BLZ | AB13: Rest Central America | AC13: OSA | AE13: GUM | AF13: xoc | AG13: IDN | AH13: SEA | AJ13: ARM | AK13: ARM | AL13: FSU | AN13: WLD | AQ13: ABW | AR13: Aruba | AS13: Total Population - Both sexes | AT13: Population - Est. & Proj. | AU13: 2014 | AV13: 1000 persons | AW13: 103.774
A14: EUR | B14: =INDEX(Regions!B:B,MATCH(A14,Regions!A:A,0)) -> Europe | C14: Bosnia and Herzegovina | D14: BA | E14: BIH | F14: 70 | G14: =INDEX(AW:AW,MATCH(E14,AQ:AQ,0))/INDEX(AW:AW,MATCH("World",AR:AR,0)) -> 0.0004773086 | H14: =IF(INDEX(Y:Y,MATCH(E14,W:W,0))=A14,"",INDEX(Y:Y,MATCH(E14,W:W,0))) | I14: =IF(INDEX(AC:AC,MATCH(E14,AA:AA,0))=A14,"",INDEX(AC:AC,MATCH(E14,AA:AA,0))) | J14: =IF(INDEX(U:U,MATCH(E14,T:T,0))=A14,"",INDEX(U:U,MATCH(E14,T:T,0))) | K14: =IF(INDEX(AH:AH,MATCH(E14,AE:AE,0))=A14,"",INDEX(AH:AH,MATCH(E14,AE:AE,0))) | S14: FSU | T14: AZE | U14: FSU | W14: BDI | X14: Burundi | Y14: SSA | AA14: BMU | AB14: Rest Central America | AC14: OSA | AE14: KIR | AF14: xoc | AG14: IDN | AH14: SEA | AJ14: ASM | AK14: OPO | AL14: OAS | AN14: WLD | AO14: American Samoa | AQ14: AUS | AR14: Australia | AS14: Total Population - Both sexes | AT14: Population - Est. & Proj. | AU14: 2014 | AV14: 1000 persons | AW14: 23596.424
A15: EUR | B15: =INDEX(Regions!B:B,MATCH(A15,Regions!A:A,0)) -> Europe | C15: Bulgaria | D15: BG | E15: BGR | F15: 100 | G15: =INDEX(AW:AW,MATCH(E15,AQ:AQ,0))/INDEX(AW:AW,MATCH("World",AR:AR,0)) -> 0.00099319496 | H15: =IF(INDEX(Y:Y,MATCH(E15,W:W,0))=A15,"",INDEX(Y:Y,MATCH(E15,W:W,0))) | I15: =IF(INDEX(AC:AC,MATCH(E15,AA:AA,0))=A15,"",INDEX(AC:AC,MATCH(E15,AA:AA,0))) | J15: =IF(INDEX(U:U,MATCH(E15,T:T,0))=A15,"",INDEX(U:U,MATCH(E15,T:T,0))) | K15: =IF(INDEX(AH:AH,MATCH(E15,AE:AE,0))=A15,"",INDEX(AH:AH,MATCH(E15,AE:AE,0))) | S15: #N/A | T15: BDI | U15: #N/A | W15: ETH | X15: Ethiopia | Y15: SSA | AA15: CYM | AB15: Rest Central America | AC15: OSA | AE15: MHL | AF15: xoc | AG15: IDN | AH15: SEA | AJ15: ATA | AK15: n/a | AL15: #N/A | AM15: #N/A | AN15: #N/A | AO15: Antartica | AQ15: AUT | AR15: Austria | AS15: Total Population - Both sexes | AT15: Population - Est. & Proj. | AU15: 2014 | AV15: 1000 persons | AW15: 8615.214
A16: EUR | B16: =INDEX(Regions!B:B,MATCH(A16,Regions!A:A,0)) -> Europe | C16: Croatia | D16: HR | E16: HRV | F16: 191 | G16: =INDEX(AW:AW,MATCH(E16,AQ:AQ,0))/INDEX(AW:AW,MATCH("World",AR:AR,0)) -> 0.00058332315 | H16: =IF(INDEX(Y:Y,MATCH(E16,W:W,0))=A16,"",INDEX(Y:Y,MATCH(E16,W:W,0))) | I16: =IF(INDEX(AC:AC,MATCH(E16,AA:AA,0))=A16,"",INDEX(AC:AC,MATCH(E16,AA:AA,0))) | J16: =IF(INDEX(U:U,MATCH(E16,T:T,0))=A16,"",INDEX(U:U,MATCH(E16,T:T,0))) | K16: =IF(INDEX(AH:AH,MATCH(E16,AE:AE,0))=A16,"",INDEX(AH:AH,MATCH(E16,AE:AE,0))) | S16: BL000000 | T16: BEL | U16: EUR | W16: KEN | X16: Kenya | Y16: SSA | AA16: CRI | AB16: Rest Central America | AC16: OSA | AE16: FSM | AF16: xoc | AG16: IDN | AH16: SEA | AJ16: ATF | AK16: OIO | AL16: SSA | AN16: WLD | AO16: French Southern Territories | AQ16: AZE | AR16: Azerbaijan | AS16: Total Population - Both sexes | AT16: Population - Est. & Proj. | AU16: 2014 | AV16: 1000 persons | AW16: 9505.622
A17: EUR | B17: =INDEX(Regions!B:B,MATCH(A17,Regions!A:A,0)) -> Europe | C17: Cyprus | D17: CY | E17: CYP | F17: 196 | G17: =INDEX(AW:AW,MATCH(E17,AQ:AQ,0))/INDEX(AW:AW,MATCH("World",AR:AR,0)) -> 0.00015794915 | H17: =IF(INDEX(Y:Y,MATCH(E17,W:W,0))=A17,"",INDEX(Y:Y,MATCH(E17,W:W,0))) | I17: =IF(INDEX(AC:AC,MATCH(E17,AA:AA,0))=A17,"",INDEX(AC:AC,MATCH(E17,AA:AA,0))) | J17: =IF(INDEX(U:U,MATCH(E17,T:T,0))=A17,"",INDEX(U:U,MATCH(E17,T:T,0))) | K17: =IF(INDEX(AH:AH,MATCH(E17,AE:AE,0))=A17,"",INDEX(AH:AH,MATCH(E17,AE:AE,0))) | S17: AFR_LDC | T17: BEN | U17: SSA | W17: RWA | X17: Rwanda | Y17: SSA | AA17: CUB | AB17: Rest Central America | AC17: OSA | AE17: NRU | AF17: xoc | AG17: IDN | AH17: SEA | AJ17: ATG | AK17: CRB | AL17: OSA | AN17: WLD | AQ17: BHS | AR17: Bahamas | AS17: Total Population - Both sexes | AT17: Population - Est. & Proj. | AU17: 2014 | AV17: 1000 persons | AW17: 370.633
A18: EUR | B18: =INDEX(Regions!B:B,MATCH(A18,Regions!A:A,0)) -> Europe | C18: Czech Republic | D18: CZ | E18: CZE | F18: 203 | G18: =INDEX(AW:AW,MATCH(E18,AQ:AQ,0))/INDEX(AW:AW,MATCH("World",AR:AR,0)) -> 0.0014517733 | H18: =IF(INDEX(Y:Y,MATCH(E18,W:W,0))=A18,"",INDEX(Y:Y,MATCH(E18,W:W,0))) | I18: =IF(INDEX(AC:AC,MATCH(E18,AA:AA,0))=A18,"",INDEX(AC:AC,MATCH(E18,AA:AA,0))) | J18: =IF(INDEX(U:U,MATCH(E18,T:T,0))=A18,"",INDEX(U:U,MATCH(E18,T:T,0))) | K18: =IF(INDEX(AH:AH,MATCH(E18,AE:AE,0))=A18,"",INDEX(AH:AH,MATCH(E18,AE:AE,0))) | S18: AFR_LDC | T18: BFA | U18: SSA | W18: TZA | X18: Tanzania | Y18: SSA | AA18: DMA | AB18: Rest Central America | AC18: OSA | AE18: NCL | AF18: xoc | AG18: IDN | AH18: SEA | AJ18: AUS | AK18: AUS | AL18: ANZ | AN18: WLD | AQ18: BHR | AR18: Bahrain | AS18: Total Population - Both sexes | AT18: Population - Est. & Proj. | AU18: 2014 | AV18: 1000 persons | AW18: 1336.075
A19: EUR | B19: =INDEX(Regions!B:B,MATCH(A19,Regions!A:A,0)) -> Europe | C19: Denmark | D19: DK | E19: DNK | F19: 208 | G19: =INDEX(AW:AW,MATCH(E19,AQ:AQ,0))/INDEX(AW:AW,MATCH("World",AR:AR,0)) -> 0.00077641813 | H19: =IF(INDEX(Y:Y,MATCH(E19,W:W,0))=A19,"",INDEX(Y:Y,MATCH(E19,W:W,0))) | I19: =IF(INDEX(AC:AC,MATCH(E19,AA:AA,0))=A19,"",INDEX(AC:AC,MATCH(E19,AA:AA,0))) | J19: =IF(INDEX(U:U,MATCH(E19,T:T,0))=A19,"",INDEX(U:U,MATCH(E19,T:T,0))) | K19: =IF(INDEX(AH:AH,MATCH(E19,AE:AE,0))=A19,"",INDEX(AH:AH,MATCH(E19,AE:AE,0))) | S19: BGD | T19: BGD | U19: OAS | W19: UGA | X19: Uganda | Y19: SSA | AA19: DOM | AB19: Rest Central America | AC19: OSA | AE19: NIU | AF19: xoc | AG19: IDN | AH19: SEA | AJ19: AUT | AK19: AUT | AL19: EUR | AN19: WLD | AQ19: BGD | AR19: Bangladesh | AS19: Total Population - Both sexes | AT19: Population - Est. & Proj. | AU19: 2014 | AV19: 1000 persons | AW19: 154517.38
A20: EUR | B20: =INDEX(Regions!B:B,MATCH(A20,Regions!A:A,0)) -> Europe | C20: Estonia | D20: EE | E20: EST | F20: 233 | G20: =INDEX(AW:AW,MATCH(E20,AQ:AQ,0))/INDEX(AW:AW,MATCH("World",AR:AR,0)) -> 0.00018042831 | H20: =IF(INDEX(Y:Y,MATCH(E20,W:W,0))=A20,"",INDEX(Y:Y,MATCH(E20,W:W,0))) | I20: =IF(INDEX(AC:AC,MATCH(E20,AA:AA,0))=A20,"",INDEX(AC:AC,MATCH(E20,AA:AA,0))) | J20: =IF(INDEX(U:U,MATCH(E20,T:T,0))=A20,"",INDEX(U:U,MATCH(E20,T:T,0))) | K20: =IF(INDEX(AH:AH,MATCH(E20,AE:AE,0))=A20,"",INDEX(AH:AH,MATCH(E20,AE:AE,0))) | S20: BG000000 | T20: BGR | U20: EUR | W20: EST | X20: Estonia | Y20: EUR | AA20: SLV | AB20: Rest Central America | AC20: OSA | AE20: MNP | AF20: xoc | AG20: IDN | AH20: SEA | AJ20: AZE | AK20: AZE | AL20: FSU | AN20: WLD | AQ20: BRB | AR20: Barbados | AS20: Total Population - Both sexes | AT20: Population - Est. & Proj. | AU20: 2014 | AV20: 1000 persons | AW20: 284.826
A21: EUR | B21: =INDEX(Regions!B:B,MATCH(A21,Regions!A:A,0)) -> Europe | C21: Finland | D21: FI | E21: FIN | F21: 246 | G21: =INDEX(AW:AW,MATCH(E21,AQ:AQ,0))/INDEX(AW:AW,MATCH("World",AR:AR,0)) -> 0.00074862143 | H21: =IF(INDEX(Y:Y,MATCH(E21,W:W,0))=A21,"",INDEX(Y:Y,MATCH(E21,W:W,0))) | I21: =IF(INDEX(AC:AC,MATCH(E21,AA:AA,0))=A21,"",INDEX(AC:AC,MATCH(E21,AA:AA,0))) | J21: =IF(INDEX(U:U,MATCH(E21,T:T,0))=A21,"",INDEX(U:U,MATCH(E21,T:T,0))) | K21: =IF(INDEX(AH:AH,MATCH(E21,AE:AE,0))=A21,"",INDEX(AH:AH,MATCH(E21,AE:AE,0))) | S21: #N/A | T21: BHR | U21: #N/A | W21: LVA | X21: Latvia | Y21: EUR | AA21: GRD | AB21: Rest Central America | AC21: OSA | AE21: PLW | AF21: xoc | AG21: IDN | AH21: SEA | AJ21: BDI | AK21: BDI | AL21: SSA | AM21: AME | AN21: WLD | AQ21: BLR | AR21: Belarus | AS21: Total Population - Both sexes | AT21: Population - Est. & Proj. | AU21: 2014 | AV21: 1000 persons | AW21: 9431.735
A22: EUR | B22: =INDEX(Regions!B:B,MATCH(A22,Regions!A:A,0)) -> Europe | C22: France | D22: FR | E22: FRA | F22: 250 | G22: =INDEX(AW:AW,MATCH(E22,AQ:AQ,0))/INDEX(AW:AW,MATCH("World",AR:AR,0)) -> 0.0087993134 | H22: =IF(INDEX(Y:Y,MATCH(E22,W:W,0))=A22,"",INDEX(Y:Y,MATCH(E22,W:W,0))) | I22: =IF(INDEX(AC:AC,MATCH(E22,AA:AA,0))=A22,"",INDEX(AC:AC,MATCH(E22,AA:AA,0))) | J22: =IF(INDEX(U:U,MATCH(E22,T:T,0))=A22,"",INDEX(U:U,MATCH(E22,T:T,0))) | K22: =IF(INDEX(AH:AH,MATCH(E22,AE:AE,0))=A22,"",INDEX(AH:AH,MATCH(E22,AE:AE,0))) | S22: MSA_ACP | T22: BHS | U22: OSA | W22: LTU | X22: Lithuania | Y22: EUR | AA22: GLP | AB22: Rest Central America | AC22: OSA | AE22: PNG | AF22: xoc | AG22: IDN | AH22: SEA | AJ22: BEL | AK22: BLX | AL22: EUR | AN22: WLD | AQ22: BEL | AR22: Belgium | AS22: Total Population - Both sexes | AT22: Population - Est. & Proj. | AU22: 2014 | AV22: 1000 persons | AW22: 11221.231
A23: EUR | B23: =INDEX(Regions!B:B,MATCH(A23,Regions!A:A,0)) -> Europe | C23: Germany | D23: DE | E23: DEU | F23: 276 | G23: =INDEX(AW:AW,MATCH(E23,AQ:AQ,0))/INDEX(AW:AW,MATCH("World",AR:AR,0)) -> 0.011164788 | H23: =IF(INDEX(Y:Y,MATCH(E23,W:W,0))=A23,"",INDEX(Y:Y,MATCH(E23,W:W,0))) | I23: =IF(INDEX(AC:AC,MATCH(E23,AA:AA,0))=A23,"",INDEX(AC:AC,MATCH(E23,AA:AA,0))) | J23: =IF(INDEX(U:U,MATCH(E23,T:T,0))=A23,"",INDEX(U:U,MATCH(E23,T:T,0))) | K23: =IF(INDEX(AH:AH,MATCH(E23,AE:AE,0))=A23,"",INDEX(AH:AH,MATCH(E23,AE:AE,0))) | S23: BA000000 | T23: BIH | U23: EUR | W23: BGR | X23: Bulgaria | Y23: EUR | AA23: GTM | AB23: Rest Central America | AC23: OSA | AE23: PCN | AF23: xoc | AG23: IDN | AH23: SEA | AJ23: BEN | AK23: BEN | AL23: SSA | AM23: AME | AN23: WLD | AQ23: BLZ | AR23: Belize | AS23: Total Population - Both sexes | AT23: Population - Est. & Proj. | AU23: 2014 | AV23: 1000 persons | AW23: 353.366
A24: EUR | B24: =INDEX(Regions!B:B,MATCH(A24,Regions!A:A,0)) -> Europe | C24: Gibraltar | D24: GI | E24: GIB | F24: 292 | G24: =INDEX(AW:AW,MATCH(E24,AQ:AQ,0))/INDEX(AW:AW,MATCH("World",AR:AR,0)) -> 4.6228452e-06 | H24: =IF(INDEX(Y:Y,MATCH(E24,W:W,0))=A24,"",INDEX(Y:Y,MATCH(E24,W:W,0))) -> NotAccounted | I24: =IF(INDEX(AC:AC,MATCH(E24,AA:AA,0))=A24,"",INDEX(AC:AC,MATCH(E24,AA:AA,0))) | J24: =IF(INDEX(U:U,MATCH(E24,T:T,0))=A24,"",INDEX(U:U,MATCH(E24,T:T,0))) -> #N/A | K24: =IF(INDEX(AH:AH,MATCH(E24,AE:AE,0))=A24,"",INDEX(AH:AH,MATCH(E24,AE:AE,0))) | S24: BEL | T24: BLR | U24: FSU | W24: HRV | X24: Croatia | Y24: EUR | AA24: HTI | AB24: Rest Central America | AC24: OSA | AE24: WSM | AF24: xoc | AG24: IDN | AH24: SEA | AJ24: BES | AK24: CRB | AL24: OSA | AN24: WLD | AO24: Bonaire, Sint Eustatius and Saba | AQ24: BEN | AR24: Benin | AS24: Total Population - Both sexes | AT24: Population - Est. & Proj. | AU24: 2014 | AV24: 1000 persons | AW24: 10286.844
A25: EUR | B25: =INDEX(Regions!B:B,MATCH(A25,Regions!A:A,0)) -> Europe | C25: Greece | D25: GR | E25: GRC | F25: 300 | G25: =INDEX(AW:AW,MATCH(E25,AQ:AQ,0))/INDEX(AW:AW,MATCH("World",AR:AR,0)) -> 0.0014668992 | H25: =IF(INDEX(Y:Y,MATCH(E25,W:W,0))=A25,"",INDEX(Y:Y,MATCH(E25,W:W,0))) | I25: =IF(INDEX(AC:AC,MATCH(E25,AA:AA,0))=A25,"",INDEX(AC:AC,MATCH(E25,AA:AA,0))) | J25: =IF(INDEX(U:U,MATCH(E25,T:T,0))=A25,"",INDEX(U:U,MATCH(E25,T:T,0))) | K25: =IF(INDEX(AH:AH,MATCH(E25,AE:AE,0))=A25,"",INDEX(AH:AH,MATCH(E25,AE:AE,0))) | S25: MSA_ACP | T25: BLZ | U25: OSA | W25: CZE | X25: CzechRep | Y25: EUR | AA25: HND | AB25: Rest Central America | AC25: OSA | AE25: SLB | AF25: xoc | AG25: IDN | AH25: SEA | AJ25: BFA | AK25: BFA | AL25: SSA | AM25: AME | AN25: WLD | AQ25: BMU | AR25: Bermuda | AS25: Total Population - Both sexes | AT25: Population - Est. & Proj. | AU25: 2014 | AV25: 1000 persons | AW25: 64.033
A26: EUR | B26: =INDEX(Regions!B:B,MATCH(A26,Regions!A:A,0)) -> Europe | C26: Holy See | D26: VA | E26: VAT | F26: 336 | G26: =INDEX(AW:AW,MATCH(E26,AQ:AQ,0))/INDEX(AW:AW,MATCH("World",AR:AR,0)) -> 1.0965978e-07 | H26: =IF(INDEX(Y:Y,MATCH(E26,W:W,0))=A26,"",INDEX(Y:Y,MATCH(E26,W:W,0))) -> NotAccounted | I26: =IF(INDEX(AC:AC,MATCH(E26,AA:AA,0))=A26,"",INDEX(AC:AC,MATCH(E26,AA:AA,0))) | J26: =IF(INDEX(U:U,MATCH(E26,T:T,0))=A26,"",INDEX(U:U,MATCH(E26,T:T,0))) -> #N/A | K26: =IF(INDEX(AH:AH,MATCH(E26,AE:AE,0))=A26,"",INDEX(AH:AH,MATCH(E26,AE:AE,0))) | S26: RSA | T26: BMU | U26: OSA | W26: HUN | X26: Hungary | Y26: EUR | AA26: JAM | AB26: Rest Central America | AC26: OSA | AE26: TKL | AF26: xoc | AG26: IDN | AH26: SEA | AJ26: BGD | AK26: BGD | AL26: OAS | AM26: SAS | AN26: WLD | AQ26: BTN | AR26: Bhutan | AS26: Total Population - Both sexes | AT26: Population - Est. & Proj. | AU26: 2014 | AV26: 1000 persons | AW26: 719.055
A27: EUR | B27: =INDEX(Regions!B:B,MATCH(A27,Regions!A:A,0)) -> Europe | C27: Hungary | D27: HU | E27: HUN | F27: 348 | G27: =INDEX(AW:AW,MATCH(E27,AQ:AQ,0))/INDEX(AW:AW,MATCH("World",AR:AR,0)) -> 0.0013440165 | H27: =IF(INDEX(Y:Y,MATCH(E27,W:W,0))=A27,"",INDEX(Y:Y,MATCH(E27,W:W,0))) | I27: =IF(INDEX(AC:AC,MATCH(E27,AA:AA,0))=A27,"",INDEX(AC:AC,MATCH(E27,AA:AA,0))) | J27: =IF(INDEX(U:U,MATCH(E27,T:T,0))=A27,"",INDEX(U:U,MATCH(E27,T:T,0))) | K27: =IF(INDEX(AH:AH,MATCH(E27,AE:AE,0))=A27,"",INDEX(AH:AH,MATCH(E27,AE:AE,0))) | S27: BOL | T27: BOL | U27: OSA | W27: POL | X27: Poland | Y27: EUR | AA27: MTQ | AB27: Rest Central America | AC27: OSA | AE27: TON | AF27: xoc | AG27: IDN | AH27: SEA | AJ27: BGR | AK27: BGR | AL27: EUR | AN27: WLD | AQ27: BOL | AR27: Bolivia (Plurinational State of) | AS27: Total Population - Both sexes | AT27: Population - Est. & Proj. | AU27: 2014 | AV27: 1000 persons | AW27: 10706.517
A28: EUR | B28: =INDEX(Regions!B:B,MATCH(A28,Regions!A:A,0)) -> Europe | C28: Iceland | D28: IS | E28: ISL | F28: 352 | G28: =INDEX(AW:AW,MATCH(E28,AQ:AQ,0))/INDEX(AW:AW,MATCH("World",AR:AR,0)) -> 4.5041933e-05 | H28: =IF(INDEX(Y:Y,MATCH(E28,W:W,0))=A28,"",INDEX(Y:Y,MATCH(E28,W:W,0))) | I28: =IF(INDEX(AC:AC,MATCH(E28,AA:AA,0))=A28,"",INDEX(AC:AC,MATCH(E28,AA:AA,0))) | J28: =IF(INDEX(U:U,MATCH(E28,T:T,0))=A28,"",INDEX(U:U,MATCH(E28,T:T,0))) | K28: =IF(INDEX(AH:AH,MATCH(E28,AE:AE,0))=A28,"",INDEX(AH:AH,MATCH(E28,AE:AE,0))) | S28: BRA | T28: BRA | U28: BRA | W28: ROU | X28: Romania | Y28: EUR | AA28: MSR | AB28: Rest Central America | AC28: OSA | AE28: TUV | AF28: xoc | AG28: IDN | AH28: SEA | AJ28: BHR | AK28: RAP | AL28: MEN | AM28: AME | AN28: WLD | AQ28: BES | AR28: Bonaire, Sint Eustatius and Saba | AS28: Total Population - Both sexes | AT28: Population - Est. & Proj. | AU28: 2014 | AV28: 1000 persons | AW28: 24.07
A29: EUR | B29: =INDEX(Regions!B:B,MATCH(A29,Regions!A:A,0)) -> Europe | C29: Ireland | D29: IE | E29: IRL | F29: 372 | G29: =INDEX(AW:AW,MATCH(E29,AQ:AQ,0))/INDEX(AW:AW,MATCH("World",AR:AR,0)) -> 0.00063422338 | H29: =IF(INDEX(Y:Y,MATCH(E29,W:W,0))=A29,"",INDEX(Y:Y,MATCH(E29,W:W,0))) | I29: =IF(INDEX(AC:AC,MATCH(E29,AA:AA,0))=A29,"",INDEX(AC:AC,MATCH(E29,AA:AA,0))) | J29: =IF(INDEX(U:U,MATCH(E29,T:T,0))=A29,"",INDEX(U:U,MATCH(E29,T:T,0))) | K29: =IF(INDEX(AH:AH,MATCH(E29,AE:AE,0))=A29,"",INDEX(AH:AH,MATCH(E29,AE:AE,0))) | S29: MSA_ACP | T29: BRB | U29: OSA | W29: SVK | X29: Slovakia | Y29: EUR | AA29: ANT | AB29: Rest Central America | AC29: OSA | AE29: UMI | AF29: xoc | AG29: IDN | AH29: SEA | AJ29: BHS | AK29: CRB | AL29: OSA | AN29: WLD | AQ29: BIH | AR29: Bosnia and Herzegovina | AS29: Total Population - Both sexes | AT29: Population - Est. & Proj. | AU29: 2014 | AV29: 1000 persons | AW29: 3482.105
A30: EUR | B30: =INDEX(Regions!B:B,MATCH(A30,Regions!A:A,0)) -> Europe | C30: Italy | D30: IT | E30: ITA | F30: 380 | G30: =INDEX(AW:AW,MATCH(E30,AQ:AQ,0))/INDEX(AW:AW,MATCH("World",AR:AR,0)) -> 0.0082806323 | H30: =IF(INDEX(Y:Y,MATCH(E30,W:W,0))=A30,"",INDEX(Y:Y,MATCH(E30,W:W,0))) | I30: =IF(INDEX(AC:AC,MATCH(E30,AA:AA,0))=A30,"",INDEX(AC:AC,MATCH(E30,AA:AA,0))) | J30: =IF(INDEX(U:U,MATCH(E30,T:T,0))=A30,"",INDEX(U:U,MATCH(E30,T:T,0))) | K30: =IF(INDEX(AH:AH,MATCH(E30,AE:AE,0))=A30,"",INDEX(AH:AH,MATCH(E30,AE:AE,0))) | S30: ASOCE_REST | T30: BRN | U30: OAS | W30: SVN | X30: Slovenia | Y30: EUR | AA30: NIC | AB30: Rest Central America | AC30: OSA | AE30: VUT | AF30: xoc | AG30: IDN | AH30: SEA | AJ30: BIH | AK30: OBN | AL30: EUR | AN30: WLD | AQ30: BWA | AR30: Botswana | AS30: Total Population - Both sexes | AT30: Population - Est. & Proj. | AU30: 2014 | AV30: 1000 persons | AW30: 2088.618
A31: EUR | B31: =INDEX(Regions!B:B,MATCH(A31,Regions!A:A,0)) -> Europe | C31: Latvia | D31: LV | E31: LVA | F31: 428 | G31: =INDEX(AW:AW,MATCH(E31,AQ:AQ,0))/INDEX(AW:AW,MATCH("World",AR:AR,0)) -> 0.00027705805 | H31: =IF(INDEX(Y:Y,MATCH(E31,W:W,0))=A31,"",INDEX(Y:Y,MATCH(E31,W:W,0))) | I31: =IF(INDEX(AC:AC,MATCH(E31,AA:AA,0))=A31,"",INDEX(AC:AC,MATCH(E31,AA:AA,0))) | J31: =IF(INDEX(U:U,MATCH(E31,T:T,0))=A31,"",INDEX(U:U,MATCH(E31,T:T,0))) | K31: =IF(INDEX(AH:AH,MATCH(E31,AE:AE,0))=A31,"",INDEX(AH:AH,MATCH(E31,AE:AE,0))) | S31: #N/A | T31: BTN | U31: #N/A | W31: AUT | X31: Austria | Y31: EUR | AA31: PAN | AB31: Rest Central America | AC31: OSA | AE31: WLF | AF31: xoc | AG31: IDN | AH31: SEA | AJ31: BLM | AK31: CRB | AL31: OSA | AN31: WLD | AO31: Saint Barthélemy | AQ31: BRA | AR31: Brazil | AS31: Total Population - Both sexes | AT31: Population - Est. & Proj. | AU31: 2014 | AV31: 1000 persons | AW31: 202763.74
A32: EUR | B32: =INDEX(Regions!B:B,MATCH(A32,Regions!A:A,0)) -> Europe | C32: Liechtenstein | D32: LI | E32: LIE | F32: 438 | G32: =INDEX(AW:AW,MATCH(E32,AQ:AQ,0))/INDEX(AW:AW,MATCH("World",AR:AR,0)) -> 5.1023326e-06 | H32: =IF(INDEX(Y:Y,MATCH(E32,W:W,0))=A32,"",INDEX(Y:Y,MATCH(E32,W:W,0))) -> NotAccounted | I32: =IF(INDEX(AC:AC,MATCH(E32,AA:AA,0))=A32,"",INDEX(AC:AC,MATCH(E32,AA:AA,0))) | J32: =IF(INDEX(U:U,MATCH(E32,T:T,0))=A32,"",INDEX(U:U,MATCH(E32,T:T,0))) -> #N/A | K32: =IF(INDEX(AH:AH,MATCH(E32,AE:AE,0))=A32,"",INDEX(AH:AH,MATCH(E32,AE:AE,0))) | S32: AFR_REST | T32: BWA | U32: SSA | W32: BEL | X32: Belgium | Y32: EUR | AA32: PRI | AB32: Rest Central America | AC32: OSA | AE32: CHN | AF32: chn | AG32: CHR | AH32: CHN | AJ32: BLR | AK32: BLR | AL32: FSU | AN32: WLD | AQ32: VGB | AR32: British Virgin Islands | AS32: Total Population - Both sexes | AT32: Population - Est. & Proj. | AU32: 2014 | AV32: 1000 persons | AW32: 28.989
A33: EUR | B33: =INDEX(Regions!B:B,MATCH(A33,Regions!A:A,0)) -> Europe | C33: Lithuania | D33: LT | E33: LTU | F33: 440 | G33: =INDEX(AW:AW,MATCH(E33,AQ:AQ,0))/INDEX(AW:AW,MATCH("World",AR:AR,0)) -> 0.00040731714 | H33: =IF(INDEX(Y:Y,MATCH(E33,W:W,0))=A33,"",INDEX(Y:Y,MATCH(E33,W:W,0))) | I33: =IF(INDEX(AC:AC,MATCH(E33,AA:AA,0))=A33,"",INDEX(AC:AC,MATCH(E33,AA:AA,0))) | J33: =IF(INDEX(U:U,MATCH(E33,T:T,0))=A33,"",INDEX(U:U,MATCH(E33,T:T,0))) | K33: =IF(INDEX(AH:AH,MATCH(E33,AE:AE,0))=A33,"",INDEX(AH:AH,MATCH(E33,AE:AE,0))) | S33: AFR_LDC | T33: CAF | U33: SSA | W33: FRA | X33: France | Y33: EUR | AA33: KNA | AB33: Rest Central America | AC33: OSA | AE33: HKG | AF33: hkg | AG33: CHR | AH33: CHN | AJ33: BLZ | AK33: BLZ | AL33: OSA | AM33: OAM | AN33: WLD | AQ33: BRN | AR33: Brunei Darussalam | AS33: Total Population - Both sexes | AT33: Population - Est. & Proj. | AU33: 2014 | AV33: 1000 persons | AW33: 409.769
A34: EUR | B34: =INDEX(Regions!B:B,MATCH(A34,Regions!A:A,0)) -> Europe | C34: Luxembourg | D34: LU | E34: LUX | F34: 442 | G34: =INDEX(AW:AW,MATCH(E34,AQ:AQ,0))/INDEX(AW:AW,MATCH("World",AR:AR,0)) -> 7.601013e-05 | H34: =IF(INDEX(Y:Y,MATCH(E34,W:W,0))=A34,"",INDEX(Y:Y,MATCH(E34,W:W,0))) | I34: =IF(INDEX(AC:AC,MATCH(E34,AA:AA,0))=A34,"",INDEX(AC:AC,MATCH(E34,AA:AA,0))) | J34: =IF(INDEX(U:U,MATCH(E34,T:T,0))=A34,"",INDEX(U:U,MATCH(E34,T:T,0))) | K34: =IF(INDEX(AH:AH,MATCH(E34,AE:AE,0))=A34,"",INDEX(AH:AH,MATCH(E34,AE:AE,0))) | S34: CAN | T34: CAN | U34: CAN | W34: DEU | X34: Germany | Y34: EUR | AA34: LCA | AB34: Rest Central America | AC34: OSA | AE34: JPN | AF34: jpn | AG34: JAP | AH34: SEA | AJ34: BMU | AK34: OAO | AL34: SSA | AN34: WLD | AO34: **Part of Atlantic Ocean aggregation, assigned to SSA | AQ34: BGR | AR34: Bulgaria | AS34: Total Population - Both sexes | AT34: Population - Est. & Proj. | AU34: 2014 | AV34: 1000 persons | AW34: 7245.646
A35: EUR | B35: =INDEX(Regions!B:B,MATCH(A35,Regions!A:A,0)) -> Europe | C35: Malta | D35: MT | E35: MLT | F35: 470 | G35: =INDEX(AW:AW,MATCH(E35,AQ:AQ,0))/INDEX(AW:AW,MATCH("World",AR:AR,0)) -> 5.8969137e-05 | H35: =IF(INDEX(Y:Y,MATCH(E35,W:W,0))=A35,"",INDEX(Y:Y,MATCH(E35,W:W,0))) | I35: =IF(INDEX(AC:AC,MATCH(E35,AA:AA,0))=A35,"",INDEX(AC:AC,MATCH(E35,AA:AA,0))) | J35: =IF(INDEX(U:U,MATCH(E35,T:T,0))=A35,"",INDEX(U:U,MATCH(E35,T:T,0))) | K35: =IF(INDEX(AH:AH,MATCH(E35,AE:AE,0))=A35,"",INDEX(AH:AH,MATCH(E35,AE:AE,0))) | S35: CH | T35: CHE | U35: EUR | W35: LUX | X35: Luxembourg | Y35: EUR | AA35: VCT | AB35: Rest Central America | AC35: OSA | AE35: KOR | AF35: kor | AG35: KOR | AH35: CHN | AJ35: BOL | AK35: BOL | AL35: OSA | AM35: OAM | AN35: WLD | AQ35: BFA | AR35: Burkina Faso | AS35: Total Population - Both sexes | AT35: Population - Est. & Proj. | AU35: 2014 | AV35: 1000 persons | AW35: 17586.03
A36: EUR | B36: =INDEX(Regions!B:B,MATCH(A36,Regions!A:A,0)) -> Europe | C36: Monaco | D36: MC | E36: MCO | F36: 492 | G36: =INDEX(AW:AW,MATCH(E36,AQ:AQ,0))/INDEX(AW:AW,MATCH("World",AR:AR,0)) -> 5.115903e-06 | H36: =IF(INDEX(Y:Y,MATCH(E36,W:W,0))=A36,"",INDEX(Y:Y,MATCH(E36,W:W,0))) -> NotAccounted | I36: =IF(INDEX(AC:AC,MATCH(E36,AA:AA,0))=A36,"",INDEX(AC:AC,MATCH(E36,AA:AA,0))) | J36: =IF(INDEX(U:U,MATCH(E36,T:T,0))=A36,"",INDEX(U:U,MATCH(E36,T:T,0))) -> #N/A | K36: =IF(INDEX(AH:AH,MATCH(E36,AE:AE,0))=A36,"",INDEX(AH:AH,MATCH(E36,AE:AE,0))) | S36: CHL | T36: CHL | U36: OSA | W36: NLD | X36: Netherlands | Y36: EUR | AA36: TTO | AB36: Rest Central America | AC36: OSA | AE36: TWN | AF36: twn | AG36: CHR | AH36: CHN | AJ36: BRA | AK36: BRA | AL36: BRA | AM36: OAM | AN36: WLD | AQ36: BDI | AR36: Burundi | AS36: Total Population - Both sexes | AT36: Population - Est. & Proj. | AU36: 2014 | AV36: 1000 persons | AW36: 9844.299
A37: EUR | B37: =INDEX(Regions!B:B,MATCH(A37,Regions!A:A,0)) -> Europe | C37: Montenegro | D37: ME | E37: MNE | F37: 499 | G37: =INDEX(AW:AW,MATCH(E37,AQ:AQ,0))/INDEX(AW:AW,MATCH("World",AR:AR,0)) -> 8.5897193e-05 | H37: =IF(INDEX(Y:Y,MATCH(E37,W:W,0))=A37,"",INDEX(Y:Y,MATCH(E37,W:W,0))) | I37: =IF(INDEX(AC:AC,MATCH(E37,AA:AA,0))=A37,"",INDEX(AC:AC,MATCH(E37,AA:AA,0))) -> #N/A | J37: =IF(INDEX(U:U,MATCH(E37,T:T,0))=A37,"",INDEX(U:U,MATCH(E37,T:T,0))) | K37: =IF(INDEX(AH:AH,MATCH(E37,AE:AE,0))=A37,"",INDEX(AH:AH,MATCH(E37,AE:AE,0))) | S37: CHN | T37: CHN | U37: CHN | W37: DNK | X37: Denmark | Y37: EUR | AA37: TCA | AB37: Rest Central America | AC37: OSA | AE37: PRK | AF37: xea | AG37: KOR | AH37: CHN | AJ37: BRB | AK37: CRB | AL37: OSA | AN37: WLD | AQ37: CPV | AR37: Cabo Verde | AS37: Total Population - Both sexes | AT37: Population - Est. & Proj. | AU37: 2014 | AV37: 1000 persons | AW37: 518.271
A38: EUR | B38: =INDEX(Regions!B:B,MATCH(A38,Regions!A:A,0)) -> Europe | C38: Netherlands | D38: NL | E38: NLD | F38: 528 | G38: =INDEX(AW:AW,MATCH(E38,AQ:AQ,0))/INDEX(AW:AW,MATCH("World",AR:AR,0)) -> 0.002315538 | H38: =IF(INDEX(Y:Y,MATCH(E38,W:W,0))=A38,"",INDEX(Y:Y,MATCH(E38,W:W,0))) | I38: =IF(INDEX(AC:AC,MATCH(E38,AA:AA,0))=A38,"",INDEX(AC:AC,MATCH(E38,AA:AA,0))) | J38: =IF(INDEX(U:U,MATCH(E38,T:T,0))=A38,"",INDEX(U:U,MATCH(E38,T:T,0))) | K38: =IF(INDEX(AH:AH,MATCH(E38,AE:AE,0))=A38,"",INDEX(AH:AH,MATCH(E38,AE:AE,0))) | S38: AFR_REST | T38: CIV | U38: SSA | W38: FIN | X38: Finland | Y38: EUR | AA38: VGB | AB38: Rest Central America | AC38: OSA | AE38: MAC | AF38: xea | AG38: KOR | AH38: CHN | AJ38: BRN | AK38: OSA | AL38: SEA | AM38: SAS | AN38: WLD | AQ38: KHM | AR38: Cambodia | AS38: Total Population - Both sexes | AT38: Population - Est. & Proj. | AU38: 2014 | AV38: 1000 persons | AW38: 15274.503
